https://wangdoc.com/javascript/features/error.html
# 1 Error 实例对象
+ 背景：JavaScript 解析或运行时，一旦发生错误，引擎就会抛出一个错误对象；所有抛出的错误都是Error构造函数的实例
+ 实例属性：
    - message：错误提示信息【也是构造函数的参数】
    - name：错误名称（非标准属性）
    - stack：错误的堆栈（非标准属性）
```js
// 示例1：
var err = new Error('出错了');
err.message // "出错了"
```
# 2 原生错误类型
## 2.1 SyntaxError 对象
+ 语法错误
## 2.2 ReferenceError 对象
+ 引用错误
## 2.3 RangeError 对象
+ 越界错误
## 2.4 TypeError 对象
+ 类型错误
## 2.5 URIError 对象
+ 编码等错误
## 2.6 EvalError 对象
+ eval错误
# 3 自定义错误
```js
// 示例1：es6
class MyError extend Error{
    constructor(m){
        super();
        this.message = m;
        this.name = "MyError";
    }
}

// 示例2：es5
function UserError(message) {
  this.message = message || '默认信息';
  this.name = 'UserError';
}
UserError.prototype = new Error();
UserError.prototype.constructor = UserError;
```
# 4 throw 语句
+ 概念：throw语句的作用是手动中断程序执行，抛出一个错误；这个错误可以是任何类型任何值【也可以是自定义类型】
```js
// 示例1：
throw 'Error！';    // 抛出一个字符串

throw 42;   // 抛出一个数值

// 抛出一个对象
throw {
  toString: function () {
    return 'Error!';
  }
};
```
# 5 try...catch 结构
+ 一旦发生错误，程序就中止执行了。JavaScript 提供了try...catch结构，允许对错误进行处理，选择是否往下执行
+ catch接受一个参数，参数为try抛出的值
```js
// 示例1：
try {
  throw "出错了";
} catch (e) {
  console.log(typeof e);    // 字符串 ”出错误“
  console.log(111);
}
console.log(222);
// 111 222
```
# 6 finally 代码块
+ try...catch结构允许在最后添加一个finally代码块，表示不管是否出现错误，都必需在最后运行的语句
```js
// 示例1：解析: 执行出错之后，直接执行finnaly代码块，然后程序终止
function cleansUp() {
  try {
    throw new Error('出错了……');
    console.log('此行不会执行');    // 不执行
  } finally {
    console.log('完成清理工作');
  }
  console.log('不执行');    // 不执行
}

cleansUp()
```
+ 执行顺序问题：`return语句的执行是排在finally代码之前，只是等finally代码执行完毕后才返回`
```js
// 示例1：
var count = 0;
function countUp() {
  try {
    return count;
  } finally {
    count++;
  }
}
countUp()   // 0
count       // 1

```
